2021-08-10 22:11:21,397 ERROR: Exception on /user/zinedine [GET] [in /Users/vajo/local/job/microblog/venv/lib/python3.7/site-packages/flask/app.py:1455]
Traceback (most recent call last):
  File "/Users/vajo/local/job/microblog/venv/lib/python3.7/site-packages/flask/app.py", line 2070, in wsgi_app
    response = self.full_dispatch_request()
  File "/Users/vajo/local/job/microblog/venv/lib/python3.7/site-packages/flask/app.py", line 1515, in full_dispatch_request
    rv = self.handle_user_exception(e)
  File "/Users/vajo/local/job/microblog/venv/lib/python3.7/site-packages/flask/app.py", line 1513, in full_dispatch_request
    rv = self.dispatch_request()
  File "/Users/vajo/local/job/microblog/venv/lib/python3.7/site-packages/flask/app.py", line 1499, in dispatch_request
    return self.ensure_sync(self.view_functions[rule.endpoint])(**req.view_args)
  File "/Users/vajo/local/job/microblog/venv/lib/python3.7/site-packages/flask_login/utils.py", line 272, in decorated_view
    return func(*args, **kwargs)
  File "/Users/vajo/local/job/microblog/app/routes.py", line 66, in user
    return render_template('user.html', user=user, posts=posts)
  File "/Users/vajo/local/job/microblog/venv/lib/python3.7/site-packages/flask/templating.py", line 150, in render_template
    ctx.app,
  File "/Users/vajo/local/job/microblog/venv/lib/python3.7/site-packages/flask/templating.py", line 128, in _render
    rv = template.render(context)
  File "/Users/vajo/local/job/microblog/venv/lib/python3.7/site-packages/jinja2/environment.py", line 1304, in render
    self.environment.handle_exception()
  File "/Users/vajo/local/job/microblog/venv/lib/python3.7/site-packages/jinja2/environment.py", line 925, in handle_exception
    raise rewrite_traceback_stack(source=source)
  File "/Users/vajo/local/job/microblog/app/templates/user.html", line 1, in top-level template code
    {% extends "base.html" %}
  File "/Users/vajo/local/job/microblog/app/templates/base.html", line 33, in top-level template code
    {% block content %}
  File "/Users/vajo/local/job/microblog/app/templates/user.html", line 18, in block 'content'
    {% if current_user.has_liked_post(post) %}
  File "/Users/vajo/local/job/microblog/venv/lib/python3.7/site-packages/jinja2/utils.py", line 84, in from_obj
    if hasattr(obj, "jinja_pass_arg"):
jinja2.exceptions.UndefinedError: 'app.models.User object' has no attribute 'has_liked_post'
2021-08-10 22:14:34,070 INFO: Microblog startup [in /Users/vajo/local/job/microblog/app/__init__.py:44]
2021-08-10 22:14:38,698 ERROR: Exception on /user/zinedine [GET] [in /Users/vajo/local/job/microblog/venv/lib/python3.7/site-packages/flask/app.py:1455]
Traceback (most recent call last):
  File "/Users/vajo/local/job/microblog/venv/lib/python3.7/site-packages/flask/app.py", line 2070, in wsgi_app
    response = self.full_dispatch_request()
  File "/Users/vajo/local/job/microblog/venv/lib/python3.7/site-packages/flask/app.py", line 1515, in full_dispatch_request
    rv = self.handle_user_exception(e)
  File "/Users/vajo/local/job/microblog/venv/lib/python3.7/site-packages/flask/app.py", line 1513, in full_dispatch_request
    rv = self.dispatch_request()
  File "/Users/vajo/local/job/microblog/venv/lib/python3.7/site-packages/flask/app.py", line 1499, in dispatch_request
    return self.ensure_sync(self.view_functions[rule.endpoint])(**req.view_args)
  File "/Users/vajo/local/job/microblog/venv/lib/python3.7/site-packages/flask_login/utils.py", line 272, in decorated_view
    return func(*args, **kwargs)
  File "/Users/vajo/local/job/microblog/app/routes.py", line 66, in user
    return render_template('user.html', user=user, posts=posts)
  File "/Users/vajo/local/job/microblog/venv/lib/python3.7/site-packages/flask/templating.py", line 150, in render_template
    ctx.app,
  File "/Users/vajo/local/job/microblog/venv/lib/python3.7/site-packages/flask/templating.py", line 128, in _render
    rv = template.render(context)
  File "/Users/vajo/local/job/microblog/venv/lib/python3.7/site-packages/jinja2/environment.py", line 1304, in render
    self.environment.handle_exception()
  File "/Users/vajo/local/job/microblog/venv/lib/python3.7/site-packages/jinja2/environment.py", line 925, in handle_exception
    raise rewrite_traceback_stack(source=source)
  File "/Users/vajo/local/job/microblog/app/templates/user.html", line 1, in top-level template code
    {% extends "base.html" %}
  File "/Users/vajo/local/job/microblog/app/templates/base.html", line 33, in top-level template code
    {% block content %}
  File "/Users/vajo/local/job/microblog/app/templates/user.html", line 18, in block 'content'
    {% if current_user.has_liked_post(post) %}
  File "/Users/vajo/local/job/microblog/app/models.py", line 53, in has_liked_post
    PostLike.post_id == post.id).count() > 0
AttributeError: 'dict' object has no attribute 'id'
2021-08-10 22:17:06,668 INFO: Microblog startup [in /Users/vajo/local/job/microblog/app/__init__.py:44]
