2021-08-21 22:09:19,654 ERROR: Exception on /api/users/4/followed [GET] [in /Users/vajo/local/job/microblog/venv/lib/python3.7/site-packages/flask/app.py:1455]
Traceback (most recent call last):
  File "/Users/vajo/local/job/microblog/venv/lib/python3.7/site-packages/flask/app.py", line 2070, in wsgi_app
    response = self.full_dispatch_request()
  File "/Users/vajo/local/job/microblog/venv/lib/python3.7/site-packages/flask/app.py", line 1516, in full_dispatch_request
    return self.finalize_request(rv)
  File "/Users/vajo/local/job/microblog/venv/lib/python3.7/site-packages/flask/app.py", line 1535, in finalize_request
    response = self.make_response(rv)
  File "/Users/vajo/local/job/microblog/venv/lib/python3.7/site-packages/flask/app.py", line 1699, in make_response
    f"The view function for {request.endpoint!r} did not"
TypeError: The view function for 'api.get_followed' did not return a valid response. The function either returned None or ended without a return statement.
2021-08-21 22:09:44,254 ERROR: Exception on /api/users/4/followers [GET] [in /Users/vajo/local/job/microblog/venv/lib/python3.7/site-packages/flask/app.py:1455]
Traceback (most recent call last):
  File "/Users/vajo/local/job/microblog/venv/lib/python3.7/site-packages/flask/app.py", line 2070, in wsgi_app
    response = self.full_dispatch_request()
  File "/Users/vajo/local/job/microblog/venv/lib/python3.7/site-packages/flask/app.py", line 1516, in full_dispatch_request
    return self.finalize_request(rv)
  File "/Users/vajo/local/job/microblog/venv/lib/python3.7/site-packages/flask/app.py", line 1535, in finalize_request
    response = self.make_response(rv)
  File "/Users/vajo/local/job/microblog/venv/lib/python3.7/site-packages/flask/app.py", line 1699, in make_response
    f"The view function for {request.endpoint!r} did not"
TypeError: The view function for 'api.get_followers' did not return a valid response. The function either returned None or ended without a return statement.
2021-08-21 22:11:02,365 ERROR: Exception on /api/users/4/followed [GET] [in /Users/vajo/local/job/microblog/venv/lib/python3.7/site-packages/flask/app.py:1455]
Traceback (most recent call last):
  File "/Users/vajo/local/job/microblog/venv/lib/python3.7/site-packages/flask/app.py", line 2070, in wsgi_app
    response = self.full_dispatch_request()
  File "/Users/vajo/local/job/microblog/venv/lib/python3.7/site-packages/flask/app.py", line 1516, in full_dispatch_request
    return self.finalize_request(rv)
  File "/Users/vajo/local/job/microblog/venv/lib/python3.7/site-packages/flask/app.py", line 1535, in finalize_request
    response = self.make_response(rv)
  File "/Users/vajo/local/job/microblog/venv/lib/python3.7/site-packages/flask/app.py", line 1699, in make_response
    f"The view function for {request.endpoint!r} did not"
TypeError: The view function for 'api.get_followed' did not return a valid response. The function either returned None or ended without a return statement.
2021-08-21 22:15:22,819 ERROR: Exception on /api/users [GET] [in /Users/vajo/local/job/microblog/venv/lib/python3.7/site-packages/flask/app.py:1455]
Traceback (most recent call last):
  File "/Users/vajo/local/job/microblog/venv/lib/python3.7/site-packages/flask/app.py", line 2070, in wsgi_app
    response = self.full_dispatch_request()
  File "/Users/vajo/local/job/microblog/venv/lib/python3.7/site-packages/flask/app.py", line 1516, in full_dispatch_request
    return self.finalize_request(rv)
  File "/Users/vajo/local/job/microblog/venv/lib/python3.7/site-packages/flask/app.py", line 1535, in finalize_request
    response = self.make_response(rv)
  File "/Users/vajo/local/job/microblog/venv/lib/python3.7/site-packages/flask/app.py", line 1699, in make_response
    f"The view function for {request.endpoint!r} did not"
TypeError: The view function for 'api.get_users' did not return a valid response. The function either returned None or ended without a return statement.
2021-08-21 22:15:31,840 INFO: Microblog startup [in /Users/vajo/local/job/microblog/app/__init__.py:53]
2021-08-21 22:15:35,297 ERROR: Exception on /api/users [GET] [in /Users/vajo/local/job/microblog/venv/lib/python3.7/site-packages/flask/app.py:1455]
Traceback (most recent call last):
  File "/Users/vajo/local/job/microblog/venv/lib/python3.7/site-packages/flask/app.py", line 2070, in wsgi_app
    response = self.full_dispatch_request()
  File "/Users/vajo/local/job/microblog/venv/lib/python3.7/site-packages/flask/app.py", line 1515, in full_dispatch_request
    rv = self.handle_user_exception(e)
  File "/Users/vajo/local/job/microblog/venv/lib/python3.7/site-packages/flask/app.py", line 1513, in full_dispatch_request
    rv = self.dispatch_request()
  File "/Users/vajo/local/job/microblog/venv/lib/python3.7/site-packages/flask/app.py", line 1499, in dispatch_request
    return self.ensure_sync(self.view_functions[rule.endpoint])(**req.view_args)
  File "/Users/vajo/local/job/microblog/app/api/users.py", line 11, in get_users
    page = request.args.get('page', 1, type=int)
NameError: name 'request' is not defined
2021-08-21 22:17:33,153 INFO: Microblog startup [in /Users/vajo/local/job/microblog/app/__init__.py:53]
2021-08-21 22:17:41,820 ERROR: Exception on /api/users [GET] [in /Users/vajo/local/job/microblog/venv/lib/python3.7/site-packages/flask/app.py:1455]
Traceback (most recent call last):
  File "/Users/vajo/local/job/microblog/venv/lib/python3.7/site-packages/flask/app.py", line 2070, in wsgi_app
    response = self.full_dispatch_request()
  File "/Users/vajo/local/job/microblog/venv/lib/python3.7/site-packages/flask/app.py", line 1515, in full_dispatch_request
    rv = self.handle_user_exception(e)
  File "/Users/vajo/local/job/microblog/venv/lib/python3.7/site-packages/flask/app.py", line 1513, in full_dispatch_request
    rv = self.dispatch_request()
  File "/Users/vajo/local/job/microblog/venv/lib/python3.7/site-packages/flask/app.py", line 1499, in dispatch_request
    return self.ensure_sync(self.view_functions[rule.endpoint])(**req.view_args)
  File "/Users/vajo/local/job/microblog/app/api/users.py", line 13, in get_users
    data = User.to_collection_dict(User.query, page, per_page, 'api.get_users')
  File "/Users/vajo/local/job/microblog/app/models.py", line 23, in to_collection_dict
    'items': [item.to_dict() for item in resources.items],
  File "/Users/vajo/local/job/microblog/app/models.py", line 23, in <listcomp>
    'items': [item.to_dict() for item in resources.items],
  File "/Users/vajo/local/job/microblog/app/models.py", line 93, in to_dict
    'last_seen': self.last_seen.isoformat() + 'Z',
AttributeError: 'NoneType' object has no attribute 'isoformat'
2021-08-21 22:17:48,217 ERROR: Exception on /api/users [GET] [in /Users/vajo/local/job/microblog/venv/lib/python3.7/site-packages/flask/app.py:1455]
Traceback (most recent call last):
  File "/Users/vajo/local/job/microblog/venv/lib/python3.7/site-packages/flask/app.py", line 2070, in wsgi_app
    response = self.full_dispatch_request()
  File "/Users/vajo/local/job/microblog/venv/lib/python3.7/site-packages/flask/app.py", line 1515, in full_dispatch_request
    rv = self.handle_user_exception(e)
  File "/Users/vajo/local/job/microblog/venv/lib/python3.7/site-packages/flask/app.py", line 1513, in full_dispatch_request
    rv = self.dispatch_request()
  File "/Users/vajo/local/job/microblog/venv/lib/python3.7/site-packages/flask/app.py", line 1499, in dispatch_request
    return self.ensure_sync(self.view_functions[rule.endpoint])(**req.view_args)
  File "/Users/vajo/local/job/microblog/app/api/users.py", line 13, in get_users
    data = User.to_collection_dict(User.query, page, per_page, 'api.get_users')
  File "/Users/vajo/local/job/microblog/app/models.py", line 23, in to_collection_dict
    'items': [item.to_dict() for item in resources.items],
  File "/Users/vajo/local/job/microblog/app/models.py", line 23, in <listcomp>
    'items': [item.to_dict() for item in resources.items],
  File "/Users/vajo/local/job/microblog/app/models.py", line 93, in to_dict
    'last_seen': self.last_seen.isoformat() + 'Z',
AttributeError: 'NoneType' object has no attribute 'isoformat'
2021-08-21 22:21:38,608 INFO: Microblog startup [in /Users/vajo/local/job/microblog/app/__init__.py:53]
2021-08-21 22:32:28,878 INFO: Microblog startup [in /Users/vajo/local/job/microblog/app/__init__.py:53]
2021-08-21 22:34:40,154 ERROR: Exception on /api/users [POST] [in /Users/vajo/local/job/microblog/venv/lib/python3.7/site-packages/flask/app.py:1455]
Traceback (most recent call last):
  File "/Users/vajo/local/job/microblog/venv/lib/python3.7/site-packages/flask/app.py", line 2070, in wsgi_app
    response = self.full_dispatch_request()
  File "/Users/vajo/local/job/microblog/venv/lib/python3.7/site-packages/flask/app.py", line 1516, in full_dispatch_request
    return self.finalize_request(rv)
  File "/Users/vajo/local/job/microblog/venv/lib/python3.7/site-packages/flask/app.py", line 1535, in finalize_request
    response = self.make_response(rv)
  File "/Users/vajo/local/job/microblog/venv/lib/python3.7/site-packages/flask/app.py", line 1699, in make_response
    f"The view function for {request.endpoint!r} did not"
TypeError: The view function for 'api.create_user' did not return a valid response. The function either returned None or ended without a return statement.
