2021-08-21 22:47:51,817 ERROR: Exception on /explore [GET] [in /Users/vajo/local/job/microblog/venv/lib/python3.7/site-packages/flask/app.py:1455]
Traceback (most recent call last):
  File "/Users/vajo/local/job/microblog/venv/lib/python3.7/site-packages/flask/app.py", line 2070, in wsgi_app
    response = self.full_dispatch_request()
  File "/Users/vajo/local/job/microblog/venv/lib/python3.7/site-packages/flask/app.py", line 1515, in full_dispatch_request
    rv = self.handle_user_exception(e)
  File "/Users/vajo/local/job/microblog/venv/lib/python3.7/site-packages/flask/app.py", line 1513, in full_dispatch_request
    rv = self.dispatch_request()
  File "/Users/vajo/local/job/microblog/venv/lib/python3.7/site-packages/flask/app.py", line 1499, in dispatch_request
    return self.ensure_sync(self.view_functions[rule.endpoint])(**req.view_args)
  File "/Users/vajo/local/job/microblog/venv/lib/python3.7/site-packages/flask_login/utils.py", line 272, in decorated_view
    return func(*args, **kwargs)
  File "/Users/vajo/local/job/microblog/app/routes.py", line 160, in explore
    next_url=next_url, prev_url=prev_url)
  File "/Users/vajo/local/job/microblog/venv/lib/python3.7/site-packages/flask/templating.py", line 150, in render_template
    ctx.app,
  File "/Users/vajo/local/job/microblog/venv/lib/python3.7/site-packages/flask/templating.py", line 128, in _render
    rv = template.render(context)
  File "/Users/vajo/local/job/microblog/venv/lib/python3.7/site-packages/jinja2/environment.py", line 1304, in render
    self.environment.handle_exception()
  File "/Users/vajo/local/job/microblog/venv/lib/python3.7/site-packages/jinja2/environment.py", line 925, in handle_exception
    raise rewrite_traceback_stack(source=source)
  File "/Users/vajo/local/job/microblog/app/templates/index.html", line 2, in top-level template code
    {% import 'bootstrap/wtf.html' as wtf %}
  File "/Users/vajo/local/job/microblog/app/templates/base.html", line 1, in top-level template code
    {% extends 'bootstrap/base.html' %}
  File "/Users/vajo/local/job/microblog/venv/lib/python3.7/site-packages/flask_bootstrap/templates/bootstrap/base.html", line 1, in top-level template code
    {% block doc -%}
  File "/Users/vajo/local/job/microblog/venv/lib/python3.7/site-packages/flask_bootstrap/templates/bootstrap/base.html", line 4, in block 'doc'
    {%- block html %}
  File "/Users/vajo/local/job/microblog/venv/lib/python3.7/site-packages/flask_bootstrap/templates/bootstrap/base.html", line 20, in block 'html'
    {% block body -%}
  File "/Users/vajo/local/job/microblog/venv/lib/python3.7/site-packages/flask_bootstrap/templates/bootstrap/base.html", line 23, in block 'body'
    {% block content -%}
  File "/Users/vajo/local/job/microblog/app/templates/base.html", line 48, in block 'content'
    {% block app_content %}{% endblock %}
  File "/Users/vajo/local/job/microblog/app/templates/index.html", line 11, in block 'app_content'
    {% include '_post.html' %}
  File "/Users/vajo/local/job/microblog/app/templates/_post.html", line 5, in top-level template code
    <img src="{{ post.author.avatar(70) }}" />
  File "/Users/vajo/local/job/microblog/venv/lib/python3.7/site-packages/jinja2/utils.py", line 84, in from_obj
    if hasattr(obj, "jinja_pass_arg"):
jinja2.exceptions.UndefinedError: 'None' has no attribute 'avatar'
2021-08-21 22:50:43,111 INFO: Microblog startup [in /Users/vajo/local/job/microblog/app/__init__.py:53]
2021-08-21 22:59:34,633 INFO: Microblog startup [in /Users/vajo/local/job/microblog/app/__init__.py:53]
2021-08-21 22:59:58,293 ERROR: Exception on /api/users/9 [PUT] [in /Users/vajo/local/job/microblog/venv/lib/python3.7/site-packages/flask/app.py:1455]
Traceback (most recent call last):
  File "/Users/vajo/local/job/microblog/venv/lib/python3.7/site-packages/flask/app.py", line 1513, in full_dispatch_request
    rv = self.dispatch_request()
  File "/Users/vajo/local/job/microblog/venv/lib/python3.7/site-packages/flask/app.py", line 1499, in dispatch_request
    return self.ensure_sync(self.view_functions[rule.endpoint])(**req.view_args)
  File "/Users/vajo/local/job/microblog/app/api/users.py", line 54, in update_user
    user = User.query.get_or_404(id)
  File "/Users/vajo/local/job/microblog/venv/lib/python3.7/site-packages/flask_sqlalchemy/__init__.py", line 462, in get_or_404
    abort(404, description=description)
  File "/Users/vajo/local/job/microblog/venv/lib/python3.7/site-packages/werkzeug/exceptions.py", line 940, in abort
    _aborter(status, *args, **kwargs)
  File "/Users/vajo/local/job/microblog/venv/lib/python3.7/site-packages/werkzeug/exceptions.py", line 923, in __call__
    raise self.mapping[code](*args, **kwargs)
werkzeug.exceptions.NotFound: 404 Not Found: The requested URL was not found on the server. If you entered the URL manually please check your spelling and try again.

During handling of the above exception, another exception occurred:

Traceback (most recent call last):
  File "/Users/vajo/local/job/microblog/venv/lib/python3.7/site-packages/flask/app.py", line 2070, in wsgi_app
    response = self.full_dispatch_request()
  File "/Users/vajo/local/job/microblog/venv/lib/python3.7/site-packages/flask/app.py", line 1515, in full_dispatch_request
    rv = self.handle_user_exception(e)
  File "/Users/vajo/local/job/microblog/venv/lib/python3.7/site-packages/flask/app.py", line 1383, in handle_user_exception
    return self.handle_http_exception(e)
  File "/Users/vajo/local/job/microblog/venv/lib/python3.7/site-packages/flask/app.py", line 1323, in handle_http_exception
    return self.ensure_sync(handler)(e)
  File "/Users/vajo/local/job/microblog/app/errors.py", line 6, in not_found_error
    return render_template('404.html'), 404
  File "/Users/vajo/local/job/microblog/venv/lib/python3.7/site-packages/flask/templating.py", line 148, in render_template
    ctx.app.jinja_env.get_or_select_template(template_name_or_list),
  File "/Users/vajo/local/job/microblog/venv/lib/python3.7/site-packages/jinja2/environment.py", line 1068, in get_or_select_template
    return self.get_template(template_name_or_list, parent, globals)
  File "/Users/vajo/local/job/microblog/venv/lib/python3.7/site-packages/jinja2/environment.py", line 997, in get_template
    return self._load_template(name, globals)
  File "/Users/vajo/local/job/microblog/venv/lib/python3.7/site-packages/jinja2/environment.py", line 958, in _load_template
    template = self.loader.load(self, name, self.make_globals(globals))
  File "/Users/vajo/local/job/microblog/venv/lib/python3.7/site-packages/jinja2/loaders.py", line 125, in load
    source, filename, uptodate = self.get_source(environment, name)
  File "/Users/vajo/local/job/microblog/venv/lib/python3.7/site-packages/flask/templating.py", line 59, in get_source
    return self._get_source_fast(environment, template)
  File "/Users/vajo/local/job/microblog/venv/lib/python3.7/site-packages/flask/templating.py", line 95, in _get_source_fast
    raise TemplateNotFound(template)
jinja2.exceptions.TemplateNotFound: 404.html
2021-08-22 14:07:38,528 INFO: Microblog startup [in /Users/vajo/local/job/microblog/app/__init__.py:53]
2021-08-22 14:08:04,896 INFO: Microblog startup [in /Users/vajo/local/job/microblog/app/__init__.py:53]
2021-08-22 14:08:12,827 INFO: Microblog startup [in /Users/vajo/local/job/microblog/app/__init__.py:53]
2021-08-22 14:15:21,174 INFO: Microblog startup [in /Users/vajo/local/job/microblog/app/__init__.py:53]
2021-08-22 14:26:21,779 INFO: Microblog startup [in /Users/vajo/local/job/microblog/app/__init__.py:53]
2021-08-22 14:34:35,319 INFO: Microblog startup [in /Users/vajo/local/job/microblog/app/__init__.py:53]
2021-08-23 22:49:26,747 INFO: Microblog startup [in /Users/vajo/local/job/microblog/app/__init__.py:53]
2021-08-23 23:01:01,472 INFO: Microblog startup [in /Users/vajo/local/job/microblog/app/__init__.py:53]
2021-08-23 23:18:11,230 INFO: Microblog startup [in /Users/vajo/local/job/microblog/app/__init__.py:53]
2021-08-23 23:18:46,007 ERROR: Exception on /api/secret [GET] [in /Users/vajo/local/job/microblog/venv/lib/python3.7/site-packages/flask/app.py:1455]
Traceback (most recent call last):
  File "/Users/vajo/local/job/microblog/venv/lib/python3.7/site-packages/flask/app.py", line 2070, in wsgi_app
    response = self.full_dispatch_request()
  File "/Users/vajo/local/job/microblog/venv/lib/python3.7/site-packages/flask/app.py", line 1515, in full_dispatch_request
    rv = self.handle_user_exception(e)
  File "/Users/vajo/local/job/microblog/venv/lib/python3.7/site-packages/flask/app.py", line 1513, in full_dispatch_request
    rv = self.dispatch_request()
  File "/Users/vajo/local/job/microblog/venv/lib/python3.7/site-packages/flask/app.py", line 1499, in dispatch_request
    return self.ensure_sync(self.view_functions[rule.endpoint])(**req.view_args)
  File "/Users/vajo/local/job/microblog/app/api/users.py", line 76, in secret
    return f'Logged in as {request.authorization.username}.'
AttributeError: 'NoneType' object has no attribute 'username'
2021-08-23 23:20:02,953 INFO: Microblog startup [in /Users/vajo/local/job/microblog/app/__init__.py:53]
2021-08-23 23:57:09,104 INFO: Microblog startup [in /Users/vajo/local/job/microblog/app/__init__.py:53]
